nohup: ignoring input
[01/Feb/2018 11:25:42] "POST /InventoryApp/update_requisitiondetails/ HTTP/1.1" 200 116
nohup: ignoring input
[01/Feb/2018 11:43:02] "POST /InventoryApp/update_requisitiondetails/ HTTP/1.1" 200 116
Performing system checks...

System check identified no issues (0 silenced).
February 01, 2018 - 11:42:24
Django version 1.11.7, using settings 'InventoryProject.settings'
Starting development server at http://0.0.0.0:20105/
Quit the server with CONTROL-C.
{"id":"6","quantityissued":"2","statusid":"2"}
2
2
Unhandled exception in thread started by <function wrapper at 0x7f881726d320>
Performing system checks...

Traceback (most recent call last):
  File "/usr/local/lib/python2.7/dist-packages/django/utils/autoreload.py", line 228, in wrapper
    fn(*args, **kwargs)
  File "/usr/local/lib/python2.7/dist-packages/django/core/management/commands/runserver.py", line 125, in inner_run
    self.check(display_num_errors=True)
  File "/usr/local/lib/python2.7/dist-packages/django/core/management/base.py", line 359, in check
    include_deployment_checks=include_deployment_checks,
  File "/usr/local/lib/python2.7/dist-packages/django/core/management/base.py", line 346, in _run_checks
    return checks.run_checks(**kwargs)
  File "/usr/local/lib/python2.7/dist-packages/django/core/checks/registry.py", line 81, in run_checks
    new_errors = check(app_configs=app_configs)
  File "/usr/local/lib/python2.7/dist-packages/django/core/checks/urls.py", line 16, in check_url_config
    return check_resolver(resolver)
  File "/usr/local/lib/python2.7/dist-packages/django/core/checks/urls.py", line 26, in check_resolver
    return check_method()
  File "/usr/local/lib/python2.7/dist-packages/django/urls/resolvers.py", line 254, in check
    for pattern in self.url_patterns:
  File "/usr/local/lib/python2.7/dist-packages/django/utils/functional.py", line 35, in __get__
    res = instance.__dict__[self.name] = self.func(instance)
  File "/usr/local/lib/python2.7/dist-packages/django/urls/resolvers.py", line 405, in url_patterns
    patterns = getattr(self.urlconf_module, "urlpatterns", self.urlconf_module)
  File "/usr/local/lib/python2.7/dist-packages/django/utils/functional.py", line 35, in __get__
    res = instance.__dict__[self.name] = self.func(instance)
  File "/usr/local/lib/python2.7/dist-packages/django/urls/resolvers.py", line 398, in urlconf_module
    return import_module(self.urlconf_name)
  File "/usr/lib/python2.7/importlib/__init__.py", line 37, in import_module
    __import__(name)
  File "/home/esp/Desktop/InventoryProject/InventoryProject/urls.py", line 18, in <module>
    from InventoryApp import urls
  File "/home/esp/Desktop/InventoryProject/InventoryApp/urls.py", line 11, in <module>
    url(r'^get_departments/',csrf_exempt(get_departments),name = 'get_departments'),
NameError: name 'get_departments' is not defined
nohup: ignoring input
[01/Feb/2018 12:26:40] "POST /InventoryApp/update_requisitiondetails/ HTTP/1.1" 200 116
[01/Feb/2018 12:26:41] "POST /InventoryApp/login/ HTTP/1.1" 200 53
[01/Feb/2018 12:26:43] "POST /InventoryApp/get_user/ HTTP/1.1" 200 151
[01/Feb/2018 12:26:44] "POST /InventoryApp/get_requisition/ HTTP/1.1" 200 526
[01/Feb/2018 12:26:44] "GET /InventoryApp/get_category/ HTTP/1.1" 200 190
[01/Feb/2018 12:26:47] "POST /InventoryApp/update_requisitiondetails/ HTTP/1.1" 200 62
[01/Feb/2018 12:26:51] "POST /InventoryApp/update_requisitiondetails/ HTTP/1.1" 200 116
[01/Feb/2018 12:26:57] "POST /InventoryApp/update_requisitiondetails/ HTTP/1.1" 200 116
[01/Feb/2018 12:43:26] "POST /InventoryApp/login/ HTTP/1.1" 200 53
[01/Feb/2018 12:43:27] "POST /InventoryApp/get_user/ HTTP/1.1" 200 151
[01/Feb/2018 12:43:28] "GET /InventoryApp/get_category/ HTTP/1.1" 200 190
[01/Feb/2018 12:43:28] "POST /InventoryApp/get_requisition/ HTTP/1.1" 200 526
[01/Feb/2018 12:44:56] "POST /InventoryApp/login/ HTTP/1.1" 200 53
[01/Feb/2018 12:44:57] "POST /InventoryApp/get_user/ HTTP/1.1" 200 151
[01/Feb/2018 12:44:58] "GET /InventoryApp/get_category/ HTTP/1.1" 200 190
[01/Feb/2018 12:44:59] "POST /InventoryApp/get_requisition/ HTTP/1.1" 200 526
Performing system checks...

System check identified no issues (0 silenced).
February 01, 2018 - 12:26:27
Django version 1.11.7, using settings 'InventoryProject.settings'
Starting development server at http://0.0.0.0:20105/
Quit the server with CONTROL-C.
{"id":"6","quantityissued":"2","statusid":"2"}
{"password":"tabitha","username":"tabitha"}
{"username":"tabitha"}
{"id":"5"}
{"id":"5","quantityissued":"2","statusid":"2"}
{"id":"5","quantityissued":"2","statusid":"2"}
{"id":"5","quantityissued":"100","statusid":"2"}
{"password":"tabitha","username":"tabitha"}
{"username":"tabitha"}
{"id":"5"}
{"password":"tabitha","username":"tabitha"}
{"username":"tabitha"}
{"id":"5"}
Unhandled exception in thread started by <function wrapper at 0x7f2e18a09320>
Performing system checks...

Traceback (most recent call last):
  File "/usr/local/lib/python2.7/dist-packages/django/utils/autoreload.py", line 228, in wrapper
    fn(*args, **kwargs)
  File "/usr/local/lib/python2.7/dist-packages/django/core/management/commands/runserver.py", line 125, in inner_run
    self.check(display_num_errors=True)
  File "/usr/local/lib/python2.7/dist-packages/django/core/management/base.py", line 359, in check
    include_deployment_checks=include_deployment_checks,
  File "/usr/local/lib/python2.7/dist-packages/django/core/management/base.py", line 346, in _run_checks
    return checks.run_checks(**kwargs)
  File "/usr/local/lib/python2.7/dist-packages/django/core/checks/registry.py", line 81, in run_checks
    new_errors = check(app_configs=app_configs)
  File "/usr/local/lib/python2.7/dist-packages/django/core/checks/urls.py", line 16, in check_url_config
    return check_resolver(resolver)
  File "/usr/local/lib/python2.7/dist-packages/django/core/checks/urls.py", line 26, in check_resolver
    return check_method()
  File "/usr/local/lib/python2.7/dist-packages/django/urls/resolvers.py", line 254, in check
    for pattern in self.url_patterns:
  File "/usr/local/lib/python2.7/dist-packages/django/utils/functional.py", line 35, in __get__
    res = instance.__dict__[self.name] = self.func(instance)
  File "/usr/local/lib/python2.7/dist-packages/django/urls/resolvers.py", line 405, in url_patterns
    patterns = getattr(self.urlconf_module, "urlpatterns", self.urlconf_module)
  File "/usr/local/lib/python2.7/dist-packages/django/utils/functional.py", line 35, in __get__
    res = instance.__dict__[self.name] = self.func(instance)
  File "/usr/local/lib/python2.7/dist-packages/django/urls/resolvers.py", line 398, in urlconf_module
    return import_module(self.urlconf_name)
  File "/usr/lib/python2.7/importlib/__init__.py", line 37, in import_module
    __import__(name)
  File "/home/esp/Desktop/InventoryProject/InventoryProject/urls.py", line 18, in <module>
    from InventoryApp import urls
  File "/home/esp/Desktop/InventoryProject/InventoryApp/urls.py", line 6, in <module>
    url(r'^login/',csrf_exempt(login),name = 'login'),
NameError: name 'login' is not defined
nohup: ignoring input
[01/Feb/2018 13:04:19] "POST /InventoryApp/get_requisitiondetails/ HTTP/1.1" 200 26
[01/Feb/2018 13:04:40] "POST /InventoryApp/get_requisitiondetails/ HTTP/1.1" 200 563
[01/Feb/2018 13:05:02] "POST /InventoryApp/get_requisition/ HTTP/1.1" 200 1797
[01/Feb/2018 13:08:36] "POST /InventoryApp/login/ HTTP/1.1" 200 53
[01/Feb/2018 13:08:38] "POST /InventoryApp/get_user/ HTTP/1.1" 200 151
[01/Feb/2018 13:08:39] "POST /InventoryApp/get_requisition/ HTTP/1.1" 200 613
[01/Feb/2018 13:08:39] "GET /InventoryApp/get_category/ HTTP/1.1" 200 190
[01/Feb/2018 13:08:44] "POST /InventoryApp/get_requisitiondetails/ HTTP/1.1" 200 222
[01/Feb/2018 13:08:45] "GET /InventoryApp/get_product/ HTTP/1.1" 200 399391
[01/Feb/2018 13:08:51] "GET /InventoryApp/get_product/ HTTP/1.1" 200 399391
[01/Feb/2018 13:10:34] "POST /InventoryApp/login/ HTTP/1.1" 200 53
[01/Feb/2018 13:10:36] "POST /InventoryApp/get_user/ HTTP/1.1" 200 151
[01/Feb/2018 13:10:39] "POST /InventoryApp/get_requisition/ HTTP/1.1" 200 613
[01/Feb/2018 13:10:39] "GET /InventoryApp/get_category/ HTTP/1.1" 200 190
[01/Feb/2018 13:10:44] "POST /InventoryApp/get_requisitiondetails/ HTTP/1.1" 200 222
[01/Feb/2018 13:11:41] "GET /InventoryApp/get_product/ HTTP/1.1" 200 399391
[2018-02-01 13:11:41,940] - Broken pipe from ('122.175.53.53', 34169)

[01/Feb/2018 13:12:47] "POST /InventoryApp/login/ HTTP/1.1" 200 53
[01/Feb/2018 13:12:49] "POST /InventoryApp/get_user/ HTTP/1.1" 200 151
[01/Feb/2018 13:12:51] "POST /InventoryApp/get_requisition/ HTTP/1.1" 200 613
[01/Feb/2018 13:12:51] "GET /InventoryApp/get_category/ HTTP/1.1" 200 190
[01/Feb/2018 13:12:58] "POST /InventoryApp/get_requisitiondetails/ HTTP/1.1" 200 222
[01/Feb/2018 13:13:00] "POST /InventoryApp/get_requisitiondetails/ HTTP/1.1" 200 222
[01/Feb/2018 13:13:06] "GET /InventoryApp/get_product/ HTTP/1.1" 200 399391
[01/Feb/2018 13:14:30] "POST /InventoryApp/login/ HTTP/1.1" 200 53
[01/Feb/2018 13:14:31] "POST /InventoryApp/get_user/ HTTP/1.1" 200 151
[01/Feb/2018 13:14:32] "GET /InventoryApp/get_category/ HTTP/1.1" 200 190
[01/Feb/2018 13:14:32] "POST /InventoryApp/get_requisition/ HTTP/1.1" 200 613
[01/Feb/2018 13:14:35] "GET /InventoryApp/get_category/ HTTP/1.1" 200 190
[01/Feb/2018 13:14:38] "POST /InventoryApp/get_requisitiondetails/ HTTP/1.1" 200 222
[01/Feb/2018 13:14:41] "GET /InventoryApp/get_product/ HTTP/1.1" 200 399391
[01/Feb/2018 13:20:20] "POST /InventoryApp/login/ HTTP/1.1" 200 53
[01/Feb/2018 13:20:21] "POST /InventoryApp/get_user/ HTTP/1.1" 200 151
[01/Feb/2018 13:20:21] "POST /InventoryApp/login/ HTTP/1.1" 200 53
[01/Feb/2018 13:20:22] "POST /InventoryApp/get_user/ HTTP/1.1" 200 151
[01/Feb/2018 13:20:22] "GET /InventoryApp/get_category/ HTTP/1.1" 200 190
[01/Feb/2018 13:20:22] "POST /InventoryApp/get_requisition/ HTTP/1.1" 200 613
[01/Feb/2018 13:20:23] "GET /InventoryApp/get_category/ HTTP/1.1" 200 190
[01/Feb/2018 13:20:23] "POST /InventoryApp/get_requisition/ HTTP/1.1" 200 613
[01/Feb/2018 13:20:26] "POST /InventoryApp/get_requisitiondetails/ HTTP/1.1" 200 199
[01/Feb/2018 13:20:27] "GET /InventoryApp/get_product/ HTTP/1.1" 200 399391
[01/Feb/2018 13:21:36] "POST /InventoryApp/login/ HTTP/1.1" 200 53
[01/Feb/2018 13:21:37] "POST /InventoryApp/get_user/ HTTP/1.1" 200 151
[01/Feb/2018 13:21:38] "GET /InventoryApp/get_category/ HTTP/1.1" 200 190
[01/Feb/2018 13:21:38] "POST /InventoryApp/get_requisition/ HTTP/1.1" 200 613
[01/Feb/2018 13:21:41] "POST /InventoryApp/get_requisitiondetails/ HTTP/1.1" 200 222
[01/Feb/2018 13:21:45] "GET /InventoryApp/get_product/ HTTP/1.1" 200 399391
[01/Feb/2018 13:23:36] "POST /InventoryApp/login/ HTTP/1.1" 200 53
[01/Feb/2018 13:23:36] "POST /InventoryApp/login/ HTTP/1.1" 200 53
[01/Feb/2018 13:23:37] "POST /InventoryApp/login/ HTTP/1.1" 200 53
[01/Feb/2018 13:23:37] "POST /InventoryApp/get_user/ HTTP/1.1" 200 151
[01/Feb/2018 13:23:38] "POST /InventoryApp/get_user/ HTTP/1.1" 200 151
[01/Feb/2018 13:23:38] "GET /InventoryApp/get_category/ HTTP/1.1" 200 190
[01/Feb/2018 13:23:38] "POST /InventoryApp/get_requisition/ HTTP/1.1" 200 613
[01/Feb/2018 13:23:44] "POST /InventoryApp/get_user/ HTTP/1.1" 200 151
[01/Feb/2018 13:23:44] "GET /InventoryApp/get_category/ HTTP/1.1" 200 190
[01/Feb/2018 13:23:48] "POST /InventoryApp/get_requisition/ HTTP/1.1" 200 613
[01/Feb/2018 13:23:59] "POST /InventoryApp/login/ HTTP/1.1" 200 53
[01/Feb/2018 13:24:00] "POST /InventoryApp/get_user/ HTTP/1.1" 200 151
[01/Feb/2018 13:24:00] "POST /InventoryApp/login/ HTTP/1.1" 200 53
[01/Feb/2018 13:24:01] "POST /InventoryApp/get_requisition/ HTTP/1.1" 200 613
[01/Feb/2018 13:24:01] "POST /InventoryApp/get_user/ HTTP/1.1" 200 151
[01/Feb/2018 13:24:01] "GET /InventoryApp/get_category/ HTTP/1.1" 200 190
[01/Feb/2018 13:24:02] "POST /InventoryApp/get_requisition/ HTTP/1.1" 200 613
[01/Feb/2018 13:24:02] "GET /InventoryApp/get_category/ HTTP/1.1" 200 190
[01/Feb/2018 13:24:05] "POST /InventoryApp/get_requisitiondetails/ HTTP/1.1" 200 222
[01/Feb/2018 13:24:07] "GET /InventoryApp/get_product/ HTTP/1.1" 200 399391
[01/Feb/2018 13:26:23] "POST /InventoryApp/login/ HTTP/1.1" 200 53
[01/Feb/2018 13:26:24] "POST /InventoryApp/get_user/ HTTP/1.1" 200 151
[01/Feb/2018 13:26:26] "GET /InventoryApp/get_category/ HTTP/1.1" 200 190
[01/Feb/2018 13:26:26] "POST /InventoryApp/get_requisition/ HTTP/1.1" 200 613
[01/Feb/2018 13:26:29] "POST /InventoryApp/get_requisitiondetails/ HTTP/1.1" 200 199
[01/Feb/2018 13:26:30] "GET /InventoryApp/get_product/ HTTP/1.1" 200 399391
Performing system checks...

System check identified no issues (0 silenced).
February 01, 2018 - 13:03:41
Django version 1.11.7, using settings 'InventoryProject.settings'
Starting development server at http://0.0.0.0:20105/
Quit the server with CONTROL-C.
{"id":"6"}
{"id":"9"}
{"id":"6"}
{"password":"tabitha","username":"tabitha"}
{"username":"tabitha"}
{"id":"5"}
{"id":"19"}
{"password":"tabitha","username":"tabitha"}
{"username":"tabitha"}
{"id":"5"}
{"id":"19"}
{"password":"tabitha","username":"tabitha"}
{"username":"tabitha"}
{"id":"5"}
{"id":"19"}
{"id":"19"}
{"password":"tabitha","username":"tabitha"}
{"username":"tabitha"}
{"id":"5"}
{"id":"19"}
{"password":"tabitha","username":"tabitha"}
{"username":"tabitha"}
{"password":"tabitha","username":"tabitha"}
{"username":"tabitha"}
{"id":"5"}
{"id":"5"}
{"id":"18"}
{"password":"tabitha","username":"tabitha"}
{"username":"tabitha"}
{"id":"5"}
{"id":"19"}
{"password":"tabitha","username":"tabitha"}
{"password":"tabitha","username":"tabitha"}
{"password":"tabitha","username":"tabitha"}
{"username":"tabitha"}
{"username":"tabitha"}
{"id":"5"}
{"username":"tabitha"}
{"id":"5"}
{"password":"tabitha","username":"tabitha"}
{"username":"tabitha"}
{"password":"tabitha","username":"tabitha"}
{"id":"5"}
{"username":"tabitha"}
{"id":"5"}
{"id":"19"}
{"password":"tabitha","username":"tabitha"}
{"username":"tabitha"}
{"id":"5"}
{"id":"18"}
Unhandled exception in thread started by <function wrapper at 0x7f6d7e73c320>
Performing system checks...

Traceback (most recent call last):
  File "/usr/local/lib/python2.7/dist-packages/django/utils/autoreload.py", line 228, in wrapper
    fn(*args, **kwargs)
  File "/usr/local/lib/python2.7/dist-packages/django/core/management/commands/runserver.py", line 125, in inner_run
    self.check(display_num_errors=True)
  File "/usr/local/lib/python2.7/dist-packages/django/core/management/base.py", line 359, in check
    include_deployment_checks=include_deployment_checks,
  File "/usr/local/lib/python2.7/dist-packages/django/core/management/base.py", line 346, in _run_checks
    return checks.run_checks(**kwargs)
  File "/usr/local/lib/python2.7/dist-packages/django/core/checks/registry.py", line 81, in run_checks
    new_errors = check(app_configs=app_configs)
  File "/usr/local/lib/python2.7/dist-packages/django/core/checks/urls.py", line 16, in check_url_config
    return check_resolver(resolver)
  File "/usr/local/lib/python2.7/dist-packages/django/core/checks/urls.py", line 26, in check_resolver
    return check_method()
  File "/usr/local/lib/python2.7/dist-packages/django/urls/resolvers.py", line 254, in check
    for pattern in self.url_patterns:
  File "/usr/local/lib/python2.7/dist-packages/django/utils/functional.py", line 35, in __get__
    res = instance.__dict__[self.name] = self.func(instance)
  File "/usr/local/lib/python2.7/dist-packages/django/urls/resolvers.py", line 405, in url_patterns
    patterns = getattr(self.urlconf_module, "urlpatterns", self.urlconf_module)
  File "/usr/local/lib/python2.7/dist-packages/django/utils/functional.py", line 35, in __get__
    res = instance.__dict__[self.name] = self.func(instance)
  File "/usr/local/lib/python2.7/dist-packages/django/urls/resolvers.py", line 398, in urlconf_module
    return import_module(self.urlconf_name)
  File "/usr/lib/python2.7/importlib/__init__.py", line 37, in import_module
    __import__(name)
  File "/home/esp/Desktop/InventoryProject/InventoryProject/urls.py", line 18, in <module>
    from InventoryApp import urls
  File "/home/esp/Desktop/InventoryProject/InventoryApp/urls.py", line 11, in <module>
    url(r'^get_departments/',csrf_exempt(get_departments),name = 'get_departments'),
NameError: name 'get_departments' is not defined
[01/Feb/2018 13:28:34] "POST /InventoryApp/get_requisition/ HTTP/1.1" 200 613
[01/Feb/2018 13:28:34] "GET /InventoryApp/get_category/ HTTP/1.1" 200 190
[01/Feb/2018 13:28:35] "POST /InventoryApp/login/ HTTP/1.1" 200 53
[01/Feb/2018 13:28:36] "POST /InventoryApp/get_user/ HTTP/1.1" 200 151
[01/Feb/2018 13:28:40] "POST /InventoryApp/get_user/ HTTP/1.1" 200 151
[01/Feb/2018 13:28:41] "GET /InventoryApp/get_category/ HTTP/1.1" 200 190
[01/Feb/2018 13:28:41] "POST /InventoryApp/get_requisition/ HTTP/1.1" 200 613
[01/Feb/2018 13:28:44] "POST /InventoryApp/get_requisition/ HTTP/1.1" 200 613
nohup: ignoring input
[01/Feb/2018 13:29:26] "POST /InventoryApp/get_userrole/ HTTP/1.1" 200 153
[01/Feb/2018 13:29:34] "POST /InventoryApp/get_userrole/ HTTP/1.1" 200 188
[01/Feb/2018 13:29:35] "POST /InventoryApp/get_requisitiondetails/ HTTP/1.1" 200 199
[01/Feb/2018 13:29:36] "GET /InventoryApp/get_product/ HTTP/1.1" 200 399391
[01/Feb/2018 13:29:58] "POST /InventoryApp/get_userrole/ HTTP/1.1" 200 104
[01/Feb/2018 13:35:37] "POST /InventoryApp/login/ HTTP/1.1" 200 53
[01/Feb/2018 13:35:38] "POST /InventoryApp/login/ HTTP/1.1" 200 53
[01/Feb/2018 13:35:38] "POST /InventoryApp/get_user/ HTTP/1.1" 200 151
[01/Feb/2018 13:35:39] "POST /InventoryApp/get_user/ HTTP/1.1" 200 151
[01/Feb/2018 13:35:40] "GET /InventoryApp/get_category/ HTTP/1.1" 200 190
[01/Feb/2018 13:35:40] "POST /InventoryApp/get_requisition/ HTTP/1.1" 200 613
[01/Feb/2018 13:35:40] "POST /InventoryApp/get_requisition/ HTTP/1.1" 200 613
[01/Feb/2018 13:35:40] "GET /InventoryApp/get_category/ HTTP/1.1" 200 190
[01/Feb/2018 13:35:43] "POST /InventoryApp/get_requisitiondetails/ HTTP/1.1" 200 199
Performing system checks...

System check identified no issues (0 silenced).
February 01, 2018 - 13:28:58
Django version 1.11.7, using settings 'InventoryProject.settings'
Starting development server at http://0.0.0.0:20105/
Quit the server with CONTROL-C.
{"userid":"6"}
{"userid":"7"}
{"id":"18"}
{"userid":"10"}
{"password":"tabitha","username":"tabitha"}
{"password":"tabitha","username":"tabitha"}
{"username":"tabitha"}
{"username":"tabitha"}
{"id":"5"}
{"id":"5"}
{"id":"18"}
Unhandled exception in thread started by <function wrapper at 0x7fd6671de320>
Performing system checks...

Traceback (most recent call last):
  File "/usr/local/lib/python2.7/dist-packages/django/utils/autoreload.py", line 228, in wrapper
    fn(*args, **kwargs)
  File "/usr/local/lib/python2.7/dist-packages/django/core/management/commands/runserver.py", line 125, in inner_run
    self.check(display_num_errors=True)
  File "/usr/local/lib/python2.7/dist-packages/django/core/management/base.py", line 359, in check
    include_deployment_checks=include_deployment_checks,
  File "/usr/local/lib/python2.7/dist-packages/django/core/management/base.py", line 346, in _run_checks
    return checks.run_checks(**kwargs)
  File "/usr/local/lib/python2.7/dist-packages/django/core/checks/registry.py", line 81, in run_checks
    new_errors = check(app_configs=app_configs)
  File "/usr/local/lib/python2.7/dist-packages/django/core/checks/urls.py", line 16, in check_url_config
    return check_resolver(resolver)
  File "/usr/local/lib/python2.7/dist-packages/django/core/checks/urls.py", line 26, in check_resolver
    return check_method()
  File "/usr/local/lib/python2.7/dist-packages/django/urls/resolvers.py", line 254, in check
    for pattern in self.url_patterns:
  File "/usr/local/lib/python2.7/dist-packages/django/utils/functional.py", line 35, in __get__
    res = instance.__dict__[self.name] = self.func(instance)
  File "/usr/local/lib/python2.7/dist-packages/django/urls/resolvers.py", line 405, in url_patterns
    patterns = getattr(self.urlconf_module, "urlpatterns", self.urlconf_module)
  File "/usr/local/lib/python2.7/dist-packages/django/utils/functional.py", line 35, in __get__
    res = instance.__dict__[self.name] = self.func(instance)
  File "/usr/local/lib/python2.7/dist-packages/django/urls/resolvers.py", line 398, in urlconf_module
    return import_module(self.urlconf_name)
  File "/usr/lib/python2.7/importlib/__init__.py", line 37, in import_module
    __import__(name)
  File "/home/esp/Desktop/InventoryProject/InventoryProject/urls.py", line 18, in <module>
    from InventoryApp import urls
  File "/home/esp/Desktop/InventoryProject/InventoryApp/urls.py", line 6, in <module>
    url(r'^login/',csrf_exempt(login),name = 'login'),
NameError: name 'login' is not defined
[01/Feb/2018 13:36:22] "POST /InventoryApp/get_user/ HTTP/1.1" 200 71
[01/Feb/2018 13:36:38] "POST /InventoryApp/get_user/ HTTP/1.1" 200 109
[01/Feb/2018 13:36:50] "POST /InventoryApp/get_user/ HTTP/1.1" 200 109
[01/Feb/2018 13:37:23] "POST /InventoryApp/get_user/ HTTP/1.1" 200 107
[01/Feb/2018 13:38:11] "POST /InventoryApp/login/ HTTP/1.1" 200 53
[01/Feb/2018 13:38:12] "POST /InventoryApp/get_user/ HTTP/1.1" 200 109
[01/Feb/2018 13:38:51] "POST /InventoryApp/login/ HTTP/1.1" 200 53
[01/Feb/2018 13:38:52] "POST /InventoryApp/get_user/ HTTP/1.1" 200 109
[01/Feb/2018 13:39:51] "POST /InventoryApp/login/ HTTP/1.1" 200 53
[01/Feb/2018 13:39:51] "POST /InventoryApp/get_user/ HTTP/1.1" 200 109
[01/Feb/2018 13:42:53] "POST /InventoryApp/login/ HTTP/1.1" 200 53
[01/Feb/2018 13:42:54] "POST /InventoryApp/get_user/ HTTP/1.1" 200 109
[01/Feb/2018 13:42:55] "GET /InventoryApp/get_category/ HTTP/1.1" 200 190
[01/Feb/2018 13:42:55] "POST /InventoryApp/get_requisition/ HTTP/1.1" 200 613
[01/Feb/2018 13:42:58] "POST /InventoryApp/get_requisitiondetails/ HTTP/1.1" 200 222
[01/Feb/2018 13:42:59] "GET /InventoryApp/get_product/ HTTP/1.1" 200 399391
[01/Feb/2018 13:50:35] "GET /InventoryApp/get_category/ HTTP/1.1" 200 190
[01/Feb/2018 13:50:40] "POST /InventoryApp/get_requisition/ HTTP/1.1" 200 18
[01/Feb/2018 14:01:13] "POST /InventoryApp/login/ HTTP/1.1" 200 53
[01/Feb/2018 14:01:14] "POST /InventoryApp/get_user/ HTTP/1.1" 200 109
[01/Feb/2018 14:01:15] "POST /InventoryApp/login/ HTTP/1.1" 200 53
[01/Feb/2018 14:01:16] "GET /InventoryApp/get_category/ HTTP/1.1" 200 190
[01/Feb/2018 14:01:16] "POST /InventoryApp/get_requisition/ HTTP/1.1" 200 613
[01/Feb/2018 14:01:17] "POST /InventoryApp/get_user/ HTTP/1.1" 200 109
[01/Feb/2018 14:01:19] "GET /InventoryApp/get_category/ HTTP/1.1" 200 190
[01/Feb/2018 14:01:19] "POST /InventoryApp/get_requisition/ HTTP/1.1" 200 613
[01/Feb/2018 14:01:21] "POST /InventoryApp/get_requisitiondetails/ HTTP/1.1" 200 199
[01/Feb/2018 14:01:29] "GET /InventoryApp/get_product/ HTTP/1.1" 200 399391
Performing system checks...

System check identified no issues (0 silenced).
February 01, 2018 - 13:35:46
Django version 1.11.7, using settings 'InventoryProject.settings'
Starting development server at http://0.0.0.0:20105/
Quit the server with CONTROL-C.
{"id":"10"}
{"username":"chanti"}
{"username":"harisai"}
{"username":"PHANI"}
{"password":"tabitha","username":"tabitha"}
{"username":"tabitha"}
{"password":"tabitha","username":"tabitha"}
{"username":"tabitha"}
{"password":"tabitha","username":"tabitha"}
{"username":"tabitha"}
{"password":"tabitha","username":"tabitha"}
{"username":"tabitha"}
{"id":"5"}
{"id":"19"}
{"id":"null"}
{"password":"tabitha","username":"tabitha"}
{"username":"tabitha"}
{"password":"tabitha","username":"tabitha"}
{"id":"5"}
{"username":"tabitha"}
{"id":"5"}
{"id":"18"}
Unhandled exception in thread started by <function wrapper at 0x7f578989d320>
Performing system checks...

Traceback (most recent call last):
  File "/usr/local/lib/python2.7/dist-packages/django/utils/autoreload.py", line 228, in wrapper
    fn(*args, **kwargs)
  File "/usr/local/lib/python2.7/dist-packages/django/core/management/commands/runserver.py", line 125, in inner_run
    self.check(display_num_errors=True)
  File "/usr/local/lib/python2.7/dist-packages/django/core/management/base.py", line 359, in check
    include_deployment_checks=include_deployment_checks,
  File "/usr/local/lib/python2.7/dist-packages/django/core/management/base.py", line 346, in _run_checks
    return checks.run_checks(**kwargs)
  File "/usr/local/lib/python2.7/dist-packages/django/core/checks/registry.py", line 81, in run_checks
    new_errors = check(app_configs=app_configs)
  File "/usr/local/lib/python2.7/dist-packages/django/core/checks/urls.py", line 16, in check_url_config
    return check_resolver(resolver)
  File "/usr/local/lib/python2.7/dist-packages/django/core/checks/urls.py", line 26, in check_resolver
    return check_method()
  File "/usr/local/lib/python2.7/dist-packages/django/urls/resolvers.py", line 254, in check
    for pattern in self.url_patterns:
  File "/usr/local/lib/python2.7/dist-packages/django/utils/functional.py", line 35, in __get__
    res = instance.__dict__[self.name] = self.func(instance)
  File "/usr/local/lib/python2.7/dist-packages/django/urls/resolvers.py", line 405, in url_patterns
    patterns = getattr(self.urlconf_module, "urlpatterns", self.urlconf_module)
  File "/usr/local/lib/python2.7/dist-packages/django/utils/functional.py", line 35, in __get__
    res = instance.__dict__[self.name] = self.func(instance)
  File "/usr/local/lib/python2.7/dist-packages/django/urls/resolvers.py", line 398, in urlconf_module
    return import_module(self.urlconf_name)
  File "/usr/lib/python2.7/importlib/__init__.py", line 37, in import_module
    __import__(name)
  File "/home/esp/Desktop/InventoryProject/InventoryProject/urls.py", line 18, in <module>
    from InventoryApp import urls
  File "/home/esp/Desktop/InventoryProject/InventoryApp/urls.py", line 6, in <module>
    url(r'^login/',csrf_exempt(login),name = 'login'),
NameError: name 'login' is not defined
[01/Feb/2018 14:19:44] "POST /InventoryApp/get_user/ HTTP/1.1" 200 364
[01/Feb/2018 14:20:04] "POST /InventoryApp/login/ HTTP/1.1" 200 53
[01/Feb/2018 14:20:05] "POST /InventoryApp/get_user/ HTTP/1.1" 200 19
[01/Feb/2018 14:20:08] "POST /InventoryApp/get_requisition/ HTTP/1.1" 200 18
[01/Feb/2018 14:20:08] "GET /InventoryApp/get_category/ HTTP/1.1" 200 190
[01/Feb/2018 14:20:22] "POST /InventoryApp/get_user/ HTTP/1.1" 200 19
[01/Feb/2018 14:20:31] "POST /InventoryApp/get_user/ HTTP/1.1" 200 196
[01/Feb/2018 14:20:56] "POST /InventoryApp/get_user/ HTTP/1.1" 200 19
[01/Feb/2018 14:21:06] "POST /InventoryApp/get_user/ HTTP/1.1" 200 291
[01/Feb/2018 14:21:53] "POST /InventoryApp/add_requisition/ HTTP/1.1" 200 115
[01/Feb/2018 14:26:43] "POST /InventoryApp/get_user/ HTTP/1.1" 200 104
[01/Feb/2018 14:27:45] "POST /InventoryApp/login/ HTTP/1.1" 200 53
[01/Feb/2018 14:27:46] "POST /InventoryApp/login/ HTTP/1.1" 200 53
[01/Feb/2018 14:27:46] "POST /InventoryApp/get_user/ HTTP/1.1" 200 104
[01/Feb/2018 14:27:47] "POST /InventoryApp/get_user/ HTTP/1.1" 200 104
[01/Feb/2018 14:28:50] "POST /InventoryApp/login/ HTTP/1.1" 200 53
[01/Feb/2018 14:28:50] "POST /InventoryApp/get_user/ HTTP/1.1" 200 104
[01/Feb/2018 14:28:51] "GET /InventoryApp/get_category/ HTTP/1.1" 200 190
[01/Feb/2018 14:28:51] "POST /InventoryApp/get_requisition/ HTTP/1.1" 200 613
[01/Feb/2018 14:30:39] "POST /InventoryApp/get_requisitiondetails/ HTTP/1.1" 200 222
[01/Feb/2018 14:30:41] "GET /InventoryApp/get_product/ HTTP/1.1" 200 399391
Performing system checks...

System check identified no issues (0 silenced).
February 01, 2018 - 14:19:28
Django version 1.11.7, using settings 'InventoryProject.settings'
Starting development server at http://0.0.0.0:20105/
Quit the server with CONTROL-C.
{"username":"PHANI"}
{"password":"tabitha","username":"tabitha"}
{"username":"tabitha"}
{"id":"null"}
{"username":"tabitha"}
{"username":"chanti"}
{"username":"johneda"}
{"username":"harisai"}
{"productcategory":"1","userid":"null","duedate":"2018-2-1","requisitiondate":""}
{"username":"tabitha"}
{"password":"tabitha","username":"tabitha"}
{"password":"tabitha","username":"tabitha"}
{"username":"tabitha"}
{"username":"tabitha"}
{"password":"tabitha","username":"tabitha"}
{"username":"tabitha"}
{"id":"5"}
{"id":"19"}
Unhandled exception in thread started by <function wrapper at 0x7f1dd6ae8320>
Performing system checks...

Traceback (most recent call last):
  File "/usr/local/lib/python2.7/dist-packages/django/utils/autoreload.py", line 228, in wrapper
    fn(*args, **kwargs)
  File "/usr/local/lib/python2.7/dist-packages/django/core/management/commands/runserver.py", line 125, in inner_run
    self.check(display_num_errors=True)
  File "/usr/local/lib/python2.7/dist-packages/django/core/management/base.py", line 359, in check
    include_deployment_checks=include_deployment_checks,
  File "/usr/local/lib/python2.7/dist-packages/django/core/management/base.py", line 346, in _run_checks
    return checks.run_checks(**kwargs)
  File "/usr/local/lib/python2.7/dist-packages/django/core/checks/registry.py", line 81, in run_checks
    new_errors = check(app_configs=app_configs)
  File "/usr/local/lib/python2.7/dist-packages/django/core/checks/urls.py", line 16, in check_url_config
    return check_resolver(resolver)
  File "/usr/local/lib/python2.7/dist-packages/django/core/checks/urls.py", line 26, in check_resolver
    return check_method()
  File "/usr/local/lib/python2.7/dist-packages/django/urls/resolvers.py", line 254, in check
    for pattern in self.url_patterns:
  File "/usr/local/lib/python2.7/dist-packages/django/utils/functional.py", line 35, in __get__
    res = instance.__dict__[self.name] = self.func(instance)
  File "/usr/local/lib/python2.7/dist-packages/django/urls/resolvers.py", line 405, in url_patterns
    patterns = getattr(self.urlconf_module, "urlpatterns", self.urlconf_module)
  File "/usr/local/lib/python2.7/dist-packages/django/utils/functional.py", line 35, in __get__
    res = instance.__dict__[self.name] = self.func(instance)
  File "/usr/local/lib/python2.7/dist-packages/django/urls/resolvers.py", line 398, in urlconf_module
    return import_module(self.urlconf_name)
  File "/usr/lib/python2.7/importlib/__init__.py", line 37, in import_module
    __import__(name)
  File "/home/esp/Desktop/InventoryProject/InventoryProject/urls.py", line 18, in <module>
    from InventoryApp import urls
  File "/home/esp/Desktop/InventoryProject/InventoryApp/urls.py", line 6, in <module>
    url(r'^login/',csrf_exempt(login),name = 'login'),
NameError: name 'login' is not defined
Unhandled exception in thread started by <function wrapper at 0x7f76920cd320>
Performing system checks...

Traceback (most recent call last):
  File "/usr/local/lib/python2.7/dist-packages/django/utils/autoreload.py", line 228, in wrapper
    fn(*args, **kwargs)
  File "/usr/local/lib/python2.7/dist-packages/django/core/management/commands/runserver.py", line 125, in inner_run
    self.check(display_num_errors=True)
  File "/usr/local/lib/python2.7/dist-packages/django/core/management/base.py", line 359, in check
    include_deployment_checks=include_deployment_checks,
  File "/usr/local/lib/python2.7/dist-packages/django/core/management/base.py", line 346, in _run_checks
    return checks.run_checks(**kwargs)
  File "/usr/local/lib/python2.7/dist-packages/django/core/checks/registry.py", line 81, in run_checks
    new_errors = check(app_configs=app_configs)
  File "/usr/local/lib/python2.7/dist-packages/django/core/checks/urls.py", line 16, in check_url_config
    return check_resolver(resolver)
  File "/usr/local/lib/python2.7/dist-packages/django/core/checks/urls.py", line 26, in check_resolver
    return check_method()
  File "/usr/local/lib/python2.7/dist-packages/django/urls/resolvers.py", line 254, in check
    for pattern in self.url_patterns:
  File "/usr/local/lib/python2.7/dist-packages/django/utils/functional.py", line 35, in __get__
    res = instance.__dict__[self.name] = self.func(instance)
  File "/usr/local/lib/python2.7/dist-packages/django/urls/resolvers.py", line 405, in url_patterns
    patterns = getattr(self.urlconf_module, "urlpatterns", self.urlconf_module)
  File "/usr/local/lib/python2.7/dist-packages/django/utils/functional.py", line 35, in __get__
    res = instance.__dict__[self.name] = self.func(instance)
  File "/usr/local/lib/python2.7/dist-packages/django/urls/resolvers.py", line 398, in urlconf_module
    return import_module(self.urlconf_name)
  File "/usr/lib/python2.7/importlib/__init__.py", line 37, in import_module
    __import__(name)
  File "/home/esp/Desktop/InventoryProject/InventoryProject/urls.py", line 18, in <module>
    from InventoryApp import urls
  File "/home/esp/Desktop/InventoryProject/InventoryApp/urls.py", line 23, in <module>
    url(r'^get_warehouse/',csrf_exempt(get_warehouse),name = 'get_warehouse'),
NameError: name 'get_warehouse' is not defined
[01/Feb/2018 14:31:06] "POST /InventoryApp/get_user/ HTTP/1.1" 200 112
[01/Feb/2018 14:31:21] "POST /InventoryApp/get_user/ HTTP/1.1" 200 112
[01/Feb/2018 14:32:43] "POST /InventoryApp/login/ HTTP/1.1" 200 53
[01/Feb/2018 14:32:44] "POST /InventoryApp/get_user/ HTTP/1.1" 200 112
[01/Feb/2018 14:33:51] "POST /InventoryApp/login/ HTTP/1.1" 200 53
[01/Feb/2018 14:33:52] "POST /InventoryApp/login/ HTTP/1.1" 200 53
[01/Feb/2018 14:33:52] "POST /InventoryApp/get_user/ HTTP/1.1" 200 112
[01/Feb/2018 14:33:53] "POST /InventoryApp/get_user/ HTTP/1.1" 200 112
[01/Feb/2018 14:33:53] "POST /InventoryApp/get_requisition/ HTTP/1.1" 200 613
[01/Feb/2018 14:33:53] "GET /InventoryApp/get_category/ HTTP/1.1" 200 190
[01/Feb/2018 14:33:54] "GET /InventoryApp/get_category/ HTTP/1.1" 200 190
[01/Feb/2018 14:33:54] "POST /InventoryApp/get_requisition/ HTTP/1.1" 200 613
[01/Feb/2018 14:34:55] "POST /InventoryApp/get_requisitiondetails/ HTTP/1.1" 200 199
[01/Feb/2018 14:34:58] "GET /InventoryApp/get_product/ HTTP/1.1" 200 399391
[01/Feb/2018 14:36:19] "POST /InventoryApp/login/ HTTP/1.1" 200 53
[01/Feb/2018 14:36:20] "POST /InventoryApp/get_user/ HTTP/1.1" 200 112
[01/Feb/2018 14:36:21] "POST /InventoryApp/get_requisition/ HTTP/1.1" 200 613
[01/Feb/2018 14:36:21] "GET /InventoryApp/get_category/ HTTP/1.1" 200 190
[01/Feb/2018 14:36:22] "POST /InventoryApp/get_requisitiondetails/ HTTP/1.1" 200 199
[01/Feb/2018 14:36:26] "GET /InventoryApp/get_product/ HTTP/1.1" 200 399391
[01/Feb/2018 14:39:39] "POST /InventoryApp/login/ HTTP/1.1" 200 53
[01/Feb/2018 14:39:40] "POST /InventoryApp/get_user/ HTTP/1.1" 200 112
[01/Feb/2018 14:39:42] "POST /InventoryApp/get_requisition/ HTTP/1.1" 200 613
[01/Feb/2018 14:39:42] "GET /InventoryApp/get_category/ HTTP/1.1" 200 190
[01/Feb/2018 14:39:44] "POST /InventoryApp/get_requisitiondetails/ HTTP/1.1" 200 222
[01/Feb/2018 14:39:46] "GET /InventoryApp/get_product/ HTTP/1.1" 200 399391
[01/Feb/2018 14:40:27] "POST /InventoryApp/login/ HTTP/1.1" 200 53
[01/Feb/2018 14:40:27] "POST /InventoryApp/get_user/ HTTP/1.1" 200 112
[01/Feb/2018 14:40:28] "POST /InventoryApp/login/ HTTP/1.1" 200 53
[01/Feb/2018 14:40:28] "GET /InventoryApp/get_category/ HTTP/1.1" 200 190
[01/Feb/2018 14:40:28] "POST /InventoryApp/get_requisition/ HTTP/1.1" 200 613
[01/Feb/2018 14:40:29] "POST /InventoryApp/get_user/ HTTP/1.1" 200 112
[01/Feb/2018 14:40:30] "GET /InventoryApp/get_category/ HTTP/1.1" 200 190
[01/Feb/2018 14:40:30] "POST /InventoryApp/get_requisition/ HTTP/1.1" 200 613
[01/Feb/2018 14:40:33] "POST /InventoryApp/get_requisitiondetails/ HTTP/1.1" 200 222
[01/Feb/2018 14:40:35] "GET /InventoryApp/get_product/ HTTP/1.1" 200 399391
[01/Feb/2018 14:48:46] "POST /InventoryApp/login/ HTTP/1.1" 200 53
[01/Feb/2018 14:48:47] "POST /InventoryApp/get_user/ HTTP/1.1" 200 112
[01/Feb/2018 14:48:48] "GET /InventoryApp/get_category/ HTTP/1.1" 200 190
[01/Feb/2018 14:48:48] "POST /InventoryApp/get_requisition/ HTTP/1.1" 200 613
[01/Feb/2018 14:48:52] "POST /InventoryApp/get_requisitiondetails/ HTTP/1.1" 200 222
[01/Feb/2018 14:48:55] "GET /InventoryApp/get_product/ HTTP/1.1" 200 399391
[01/Feb/2018 14:49:20] "POST /InventoryApp/get_requisitiondetails/ HTTP/1.1" 200 222
[01/Feb/2018 14:49:22] "GET /InventoryApp/get_product/ HTTP/1.1" 200 399391
[01/Feb/2018 14:49:31] "POST /InventoryApp/get_requisitiondetails/ HTTP/1.1" 200 759
[01/Feb/2018 14:49:35] "GET /InventoryApp/get_product/ HTTP/1.1" 200 399391
[01/Feb/2018 14:49:57] "POST /InventoryApp/add_requisition/ HTTP/1.1" 200 77
[01/Feb/2018 14:50:04] "POST /InventoryApp/add_requisition/ HTTP/1.1" 200 52
[01/Feb/2018 14:50:05] "POST /InventoryApp/get_requisitiondetails/ HTTP/1.1" 200 759
[01/Feb/2018 14:50:10] "GET /InventoryApp/get_product/ HTTP/1.1" 200 399391
[01/Feb/2018 14:50:25] "POST /InventoryApp/add_requisitiondetails/ HTTP/1.1" 200 60
[01/Feb/2018 14:50:35] "POST /InventoryApp/get_requisitiondetails/ HTTP/1.1" 200 199
[01/Feb/2018 14:50:37] "GET /InventoryApp/get_category/ HTTP/1.1" 200 190
[01/Feb/2018 14:50:37] "POST /InventoryApp/get_requisition/ HTTP/1.1" 200 812
[01/Feb/2018 14:50:41] "GET /InventoryApp/get_product/ HTTP/1.1" 200 399391
[01/Feb/2018 14:50:43] "POST /InventoryApp/get_requisitiondetails/ HTTP/1.1" 200 26
[01/Feb/2018 14:50:47] "GET /InventoryApp/get_product/ HTTP/1.1" 200 399391
[01/Feb/2018 14:51:04] "POST /InventoryApp/login/ HTTP/1.1" 200 53
[01/Feb/2018 14:51:04] "POST /InventoryApp/get_user/ HTTP/1.1" 200 112
[01/Feb/2018 14:51:05] "POST /InventoryApp/login/ HTTP/1.1" 200 53
[01/Feb/2018 14:51:05] "POST /InventoryApp/get_user/ HTTP/1.1" 200 112
[01/Feb/2018 14:51:05] "POST /InventoryApp/get_requisition/ HTTP/1.1" 200 812
[01/Feb/2018 14:51:05] "GET /InventoryApp/get_category/ HTTP/1.1" 200 190
[01/Feb/2018 14:51:06] "GET /InventoryApp/get_category/ HTTP/1.1" 200 190
[01/Feb/2018 14:51:06] "POST /InventoryApp/get_requisition/ HTTP/1.1" 200 812
[01/Feb/2018 14:51:09] "POST /InventoryApp/get_requisitiondetails/ HTTP/1.1" 200 26
[01/Feb/2018 14:51:12] "GET /InventoryApp/get_product/ HTTP/1.1" 200 399391
[01/Feb/2018 14:51:41] "POST /InventoryApp/get_requisitiondetails/ HTTP/1.1" 200 26
[01/Feb/2018 14:51:46] "GET /InventoryApp/get_product/ HTTP/1.1" 200 399391
[01/Feb/2018 15:04:55] "POST /InventoryApp/login/ HTTP/1.1" 200 53
[01/Feb/2018 15:04:56] "POST /InventoryApp/get_user/ HTTP/1.1" 200 112
[01/Feb/2018 15:04:56] "POST /InventoryApp/login/ HTTP/1.1" 200 53
[01/Feb/2018 15:04:57] "GET /InventoryApp/get_category/ HTTP/1.1" 200 190
[01/Feb/2018 15:04:57] "POST /InventoryApp/get_requisition/ HTTP/1.1" 200 812
[01/Feb/2018 15:04:57] "POST /InventoryApp/get_user/ HTTP/1.1" 200 112
[01/Feb/2018 15:04:58] "GET /InventoryApp/get_category/ HTTP/1.1" 200 190
[01/Feb/2018 15:04:58] "POST /InventoryApp/get_requisition/ HTTP/1.1" 200 812
[01/Feb/2018 15:05:01] "POST /InventoryApp/get_requisitiondetails/ HTTP/1.1" 200 26
[01/Feb/2018 15:05:04] "GET /InventoryApp/get_product/ HTTP/1.1" 200 399391
Performing system checks...

System check identified no issues (0 silenced).
February 01, 2018 - 14:30:57
Django version 1.11.7, using settings 'InventoryProject.settings'
Starting development server at http://0.0.0.0:20105/
Quit the server with CONTROL-C.
{"username":"tabitha"}
{"username":"johneda"}
{"password":"tabitha","username":"tabitha"}
{"username":"tabitha"}
{"password":"tabitha","username":"tabitha"}
{"password":"tabitha","username":"tabitha"}
{"username":"tabitha"}
{"username":"tabitha"}
{"id":"5"}
{"id":"5"}
{"id":"18"}
{"password":"tabitha","username":"tabitha"}
{"username":"tabitha"}
{"id":"5"}
{"id":"18"}
{"password":"tabitha","username":"tabitha"}
{"username":"tabitha"}
{"id":"5"}
{"id":"19"}
{"password":"tabitha","username":"tabitha"}
{"username":"tabitha"}
{"password":"tabitha","username":"tabitha"}
{"id":"5"}
{"username":"tabitha"}
{"id":"5"}
{"id":"19"}
{"password":"tabitha","username":"tabitha"}
{"username":"tabitha"}
{"id":"5"}
{"id":"19"}
{"id":"19"}
{"id":"2"}
{"productcategory":"null","userid":"5","duedate":"","requisitiondate":""}
{"productcategory":"1","userid":"5","duedate":"2018-2-1","requisitiondate":""}
{"id":"2"}
{"requisitionid":"2","productid":"8","quantity":"8"}
{"id":"18"}
{"id":"5"}
{"id":"20"}
{"password":"tabitha","username":"tabitha"}
{"username":"tabitha"}
{"password":"tabitha","username":"tabitha"}
{"username":"tabitha"}
{"id":"5"}
{"id":"5"}
{"id":"20"}
{"id":"20"}
{"password":"tabitha","username":"tabitha"}
{"username":"tabitha"}
{"password":"tabitha","username":"tabitha"}
{"id":"5"}
{"username":"tabitha"}
{"id":"5"}
{"id":"20"}
Unhandled exception in thread started by <function wrapper at 0x7f453fc00320>
Performing system checks...

Traceback (most recent call last):
  File "/usr/local/lib/python2.7/dist-packages/django/utils/autoreload.py", line 228, in wrapper
    fn(*args, **kwargs)
  File "/usr/local/lib/python2.7/dist-packages/django/core/management/commands/runserver.py", line 125, in inner_run
    self.check(display_num_errors=True)
  File "/usr/local/lib/python2.7/dist-packages/django/core/management/base.py", line 359, in check
    include_deployment_checks=include_deployment_checks,
  File "/usr/local/lib/python2.7/dist-packages/django/core/management/base.py", line 346, in _run_checks
    return checks.run_checks(**kwargs)
  File "/usr/local/lib/python2.7/dist-packages/django/core/checks/registry.py", line 81, in run_checks
    new_errors = check(app_configs=app_configs)
  File "/usr/local/lib/python2.7/dist-packages/django/core/checks/urls.py", line 16, in check_url_config
    return check_resolver(resolver)
  File "/usr/local/lib/python2.7/dist-packages/django/core/checks/urls.py", line 26, in check_resolver
    return check_method()
  File "/usr/local/lib/python2.7/dist-packages/django/urls/resolvers.py", line 254, in check
    for pattern in self.url_patterns:
  File "/usr/local/lib/python2.7/dist-packages/django/utils/functional.py", line 35, in __get__
    res = instance.__dict__[self.name] = self.func(instance)
  File "/usr/local/lib/python2.7/dist-packages/django/urls/resolvers.py", line 405, in url_patterns
    patterns = getattr(self.urlconf_module, "urlpatterns", self.urlconf_module)
  File "/usr/local/lib/python2.7/dist-packages/django/utils/functional.py", line 35, in __get__
    res = instance.__dict__[self.name] = self.func(instance)
  File "/usr/local/lib/python2.7/dist-packages/django/urls/resolvers.py", line 398, in urlconf_module
    return import_module(self.urlconf_name)
  File "/usr/lib/python2.7/importlib/__init__.py", line 37, in import_module
    __import__(name)
  File "/home/esp/Desktop/InventoryProject/InventoryProject/urls.py", line 18, in <module>
    from InventoryApp import urls
  File "/home/esp/Desktop/InventoryProject/InventoryApp/urls.py", line 17, in <module>
    url(r'^update_userrole/',csrf_exempt(update_userrole),name = 'update_userrole'),
NameError: name 'update_userrole' is not defined
Unhandled exception in thread started by <function wrapper at 0x7fa9489b9320>
Performing system checks...

Traceback (most recent call last):
  File "/usr/local/lib/python2.7/dist-packages/django/utils/autoreload.py", line 228, in wrapper
    fn(*args, **kwargs)
  File "/usr/local/lib/python2.7/dist-packages/django/core/management/commands/runserver.py", line 125, in inner_run
    self.check(display_num_errors=True)
  File "/usr/local/lib/python2.7/dist-packages/django/core/management/base.py", line 359, in check
    include_deployment_checks=include_deployment_checks,
  File "/usr/local/lib/python2.7/dist-packages/django/core/management/base.py", line 346, in _run_checks
    return checks.run_checks(**kwargs)
  File "/usr/local/lib/python2.7/dist-packages/django/core/checks/registry.py", line 81, in run_checks
    new_errors = check(app_configs=app_configs)
  File "/usr/local/lib/python2.7/dist-packages/django/core/checks/urls.py", line 16, in check_url_config
    return check_resolver(resolver)
  File "/usr/local/lib/python2.7/dist-packages/django/core/checks/urls.py", line 26, in check_resolver
    return check_method()
  File "/usr/local/lib/python2.7/dist-packages/django/urls/resolvers.py", line 254, in check
    for pattern in self.url_patterns:
  File "/usr/local/lib/python2.7/dist-packages/django/utils/functional.py", line 35, in __get__
    res = instance.__dict__[self.name] = self.func(instance)
  File "/usr/local/lib/python2.7/dist-packages/django/urls/resolvers.py", line 405, in url_patterns
    patterns = getattr(self.urlconf_module, "urlpatterns", self.urlconf_module)
  File "/usr/local/lib/python2.7/dist-packages/django/utils/functional.py", line 35, in __get__
    res = instance.__dict__[self.name] = self.func(instance)
  File "/usr/local/lib/python2.7/dist-packages/django/urls/resolvers.py", line 398, in urlconf_module
    return import_module(self.urlconf_name)
  File "/usr/lib/python2.7/importlib/__init__.py", line 37, in import_module
    __import__(name)
  File "/home/esp/Desktop/InventoryProject/InventoryProject/urls.py", line 18, in <module>
    from InventoryApp import urls
  File "/home/esp/Desktop/InventoryProject/InventoryApp/urls.py", line 6, in <module>
    url(r'^login/',csrf_exempt(login),name = 'login'),
NameError: name 'login' is not defined
Unhandled exception in thread started by <function wrapper at 0x7f3af7f0c320>
Performing system checks...

Traceback (most recent call last):
  File "/usr/local/lib/python2.7/dist-packages/django/utils/autoreload.py", line 228, in wrapper
    fn(*args, **kwargs)
  File "/usr/local/lib/python2.7/dist-packages/django/core/management/commands/runserver.py", line 125, in inner_run
    self.check(display_num_errors=True)
  File "/usr/local/lib/python2.7/dist-packages/django/core/management/base.py", line 359, in check
    include_deployment_checks=include_deployment_checks,
  File "/usr/local/lib/python2.7/dist-packages/django/core/management/base.py", line 346, in _run_checks
    return checks.run_checks(**kwargs)
  File "/usr/local/lib/python2.7/dist-packages/django/core/checks/registry.py", line 81, in run_checks
    new_errors = check(app_configs=app_configs)
  File "/usr/local/lib/python2.7/dist-packages/django/core/checks/urls.py", line 16, in check_url_config
    return check_resolver(resolver)
  File "/usr/local/lib/python2.7/dist-packages/django/core/checks/urls.py", line 26, in check_resolver
    return check_method()
  File "/usr/local/lib/python2.7/dist-packages/django/urls/resolvers.py", line 254, in check
    for pattern in self.url_patterns:
  File "/usr/local/lib/python2.7/dist-packages/django/utils/functional.py", line 35, in __get__
    res = instance.__dict__[self.name] = self.func(instance)
  File "/usr/local/lib/python2.7/dist-packages/django/urls/resolvers.py", line 405, in url_patterns
    patterns = getattr(self.urlconf_module, "urlpatterns", self.urlconf_module)
  File "/usr/local/lib/python2.7/dist-packages/django/utils/functional.py", line 35, in __get__
    res = instance.__dict__[self.name] = self.func(instance)
  File "/usr/local/lib/python2.7/dist-packages/django/urls/resolvers.py", line 398, in urlconf_module
    return import_module(self.urlconf_name)
  File "/usr/lib/python2.7/importlib/__init__.py", line 37, in import_module
    __import__(name)
  File "/home/esp/Desktop/InventoryProject/InventoryProject/urls.py", line 18, in <module>
    from InventoryApp import urls
  File "/home/esp/Desktop/InventoryProject/InventoryApp/urls.py", line 3, in <module>
    from InventoryApp.views import *
  File "/home/esp/Desktop/InventoryProject/InventoryApp/views.py", line 1597
    output_str += ",location
                           ^
SyntaxError: EOL while scanning string literal
Unhandled exception in thread started by <function wrapper at 0x7fbc01a10320>
Performing system checks...

Traceback (most recent call last):
  File "/usr/local/lib/python2.7/dist-packages/django/utils/autoreload.py", line 228, in wrapper
    fn(*args, **kwargs)
  File "/usr/local/lib/python2.7/dist-packages/django/core/management/commands/runserver.py", line 125, in inner_run
    self.check(display_num_errors=True)
  File "/usr/local/lib/python2.7/dist-packages/django/core/management/base.py", line 359, in check
    include_deployment_checks=include_deployment_checks,
  File "/usr/local/lib/python2.7/dist-packages/django/core/management/base.py", line 346, in _run_checks
    return checks.run_checks(**kwargs)
  File "/usr/local/lib/python2.7/dist-packages/django/core/checks/registry.py", line 81, in run_checks
    new_errors = check(app_configs=app_configs)
  File "/usr/local/lib/python2.7/dist-packages/django/core/checks/urls.py", line 16, in check_url_config
    return check_resolver(resolver)
  File "/usr/local/lib/python2.7/dist-packages/django/core/checks/urls.py", line 26, in check_resolver
    return check_method()
  File "/usr/local/lib/python2.7/dist-packages/django/urls/resolvers.py", line 254, in check
    for pattern in self.url_patterns:
  File "/usr/local/lib/python2.7/dist-packages/django/utils/functional.py", line 35, in __get__
    res = instance.__dict__[self.name] = self.func(instance)
  File "/usr/local/lib/python2.7/dist-packages/django/urls/resolvers.py", line 405, in url_patterns
    patterns = getattr(self.urlconf_module, "urlpatterns", self.urlconf_module)
  File "/usr/local/lib/python2.7/dist-packages/django/utils/functional.py", line 35, in __get__
    res = instance.__dict__[self.name] = self.func(instance)
  File "/usr/local/lib/python2.7/dist-packages/django/urls/resolvers.py", line 398, in urlconf_module
    return import_module(self.urlconf_name)
  File "/usr/lib/python2.7/importlib/__init__.py", line 37, in import_module
    __import__(name)
  File "/home/esp/Desktop/InventoryProject/InventoryProject/urls.py", line 18, in <module>
    from InventoryApp import urls
  File "/home/esp/Desktop/InventoryProject/InventoryApp/urls.py", line 3, in <module>
    from InventoryApp.views import *
  File "/home/esp/Desktop/InventoryProject/InventoryApp/views.py", line 2345
    output = '{"error_code":"2", "error_desc": "GET is not suppo
                                                               ^
SyntaxError: EOL while scanning string literal
Unhandled exception in thread started by <function wrapper at 0x7f81d5463320>
Performing system checks...

Traceback (most recent call last):
  File "/usr/local/lib/python2.7/dist-packages/django/utils/autoreload.py", line 228, in wrapper
    fn(*args, **kwargs)
  File "/usr/local/lib/python2.7/dist-packages/django/core/management/commands/runserver.py", line 125, in inner_run
    self.check(display_num_errors=True)
  File "/usr/local/lib/python2.7/dist-packages/django/core/management/base.py", line 359, in check
    include_deployment_checks=include_deployment_checks,
  File "/usr/local/lib/python2.7/dist-packages/django/core/management/base.py", line 346, in _run_checks
    return checks.run_checks(**kwargs)
  File "/usr/local/lib/python2.7/dist-packages/django/core/checks/registry.py", line 81, in run_checks
    new_errors = check(app_configs=app_configs)
  File "/usr/local/lib/python2.7/dist-packages/django/core/checks/urls.py", line 16, in check_url_config
    return check_resolver(resolver)
  File "/usr/local/lib/python2.7/dist-packages/django/core/checks/urls.py", line 26, in check_resolver
    return check_method()
  File "/usr/local/lib/python2.7/dist-packages/django/urls/resolvers.py", line 254, in check
    for pattern in self.url_patterns:
  File "/usr/local/lib/python2.7/dist-packages/django/utils/functional.py", line 35, in __get__
    res = instance.__dict__[self.name] = self.func(instance)
  File "/usr/local/lib/python2.7/dist-packages/django/urls/resolvers.py", line 405, in url_patterns
    patterns = getattr(self.urlconf_module, "urlpatterns", self.urlconf_module)
  File "/usr/local/lib/python2.7/dist-packages/django/utils/functional.py", line 35, in __get__
    res = instance.__dict__[self.name] = self.func(instance)
  File "/usr/local/lib/python2.7/dist-packages/django/urls/resolvers.py", line 398, in urlconf_module
    return import_module(self.urlconf_name)
  File "/usr/lib/python2.7/importlib/__init__.py", line 37, in import_module
    __import__(name)
  File "/home/esp/Desktop/InventoryProject/InventoryProject/urls.py", line 18, in <module>
    from InventoryApp import urls
  File "/home/esp/Desktop/InventoryProject/InventoryApp/urls.py", line 48, in <module>
    url(r'^get_materialtype/',csrf_exempt(get_materialtype),name = 'get_materialtype'),
NameError: name 'get_materialtype' is not defined
nohup: ignoring input
[01/Feb/2018 15:07:05] "POST /InventoryApp/get_user/ HTTP/1.1" 200 112
[01/Feb/2018 15:08:04] "POST /InventoryApp/login/ HTTP/1.1" 200 53
[01/Feb/2018 15:08:04] "POST /InventoryApp/get_user/ HTTP/1.1" 200 112
[01/Feb/2018 15:08:06] "POST /InventoryApp/get_requisition/ HTTP/1.1" 200 812
[01/Feb/2018 15:08:06] "GET /InventoryApp/get_category/ HTTP/1.1" 200 190
[01/Feb/2018 15:08:11] "POST /InventoryApp/get_requisitiondetails/ HTTP/1.1" 200 26
[01/Feb/2018 15:08:14] "GET /InventoryApp/get_product/ HTTP/1.1" 200 399391
[01/Feb/2018 15:10:14] "POST /InventoryApp/login/ HTTP/1.1" 200 53
[01/Feb/2018 15:10:18] "POST /InventoryApp/get_user/ HTTP/1.1" 200 112
[01/Feb/2018 15:10:20] "POST /InventoryApp/get_requisition/ HTTP/1.1" 200 812
[01/Feb/2018 15:10:20] "GET /InventoryApp/get_category/ HTTP/1.1" 200 190
[01/Feb/2018 15:10:23] "POST /InventoryApp/get_requisition/ HTTP/1.1" 200 812
[01/Feb/2018 15:10:24] "GET /InventoryApp/get_category/ HTTP/1.1" 200 190
[01/Feb/2018 15:12:18] "POST /InventoryApp/login/ HTTP/1.1" 200 53
[01/Feb/2018 15:12:19] "POST /InventoryApp/get_user/ HTTP/1.1" 200 112
[01/Feb/2018 15:12:20] "POST /InventoryApp/login/ HTTP/1.1" 200 53
[01/Feb/2018 15:12:20] "POST /InventoryApp/get_requisition/ HTTP/1.1" 200 812
[01/Feb/2018 15:12:20] "GET /InventoryApp/get_category/ HTTP/1.1" 200 190
[01/Feb/2018 15:12:20] "POST /InventoryApp/get_user/ HTTP/1.1" 200 112
[01/Feb/2018 15:12:21] "GET /InventoryApp/get_category/ HTTP/1.1" 200 190
[01/Feb/2018 15:12:21] "POST /InventoryApp/get_requisition/ HTTP/1.1" 200 812
[01/Feb/2018 15:12:33] "GET /InventoryApp/get_product/ HTTP/1.1" 200 399391
[01/Feb/2018 15:13:52] "POST /InventoryApp/login/ HTTP/1.1" 200 53
[01/Feb/2018 15:13:52] "POST /InventoryApp/get_user/ HTTP/1.1" 200 112
[01/Feb/2018 15:13:54] "POST /InventoryApp/get_requisition/ HTTP/1.1" 200 812
[01/Feb/2018 15:13:54] "GET /InventoryApp/get_category/ HTTP/1.1" 200 190
[01/Feb/2018 15:14:04] "GET /InventoryApp/get_product/ HTTP/1.1" 200 399391
[01/Feb/2018 15:20:10] "POST /InventoryApp/login/ HTTP/1.1" 200 53
[01/Feb/2018 15:20:12] "POST /InventoryApp/get_user/ HTTP/1.1" 200 112
[01/Feb/2018 15:20:14] "GET /InventoryApp/get_category/ HTTP/1.1" 200 190
[01/Feb/2018 15:20:14] "POST /InventoryApp/get_requisition/ HTTP/1.1" 200 812
[01/Feb/2018 15:20:26] "GET /InventoryApp/get_product/ HTTP/1.1" 200 399391
[01/Feb/2018 15:22:49] "POST /InventoryApp/login/ HTTP/1.1" 200 53
[01/Feb/2018 15:22:52] "POST /InventoryApp/login/ HTTP/1.1" 200 53
[01/Feb/2018 15:22:58] "POST /InventoryApp/login/ HTTP/1.1" 200 53
[01/Feb/2018 15:22:58] "POST /InventoryApp/get_user/ HTTP/1.1" 200 112
[01/Feb/2018 15:22:59] "POST /InventoryApp/login/ HTTP/1.1" 200 53
[01/Feb/2018 15:22:59] "POST /InventoryApp/login/ HTTP/1.1" 200 53
[01/Feb/2018 15:23:04] "POST /InventoryApp/get_user/ HTTP/1.1" 200 112
[01/Feb/2018 15:23:04] "POST /InventoryApp/get_requisition/ HTTP/1.1" 200 812
[01/Feb/2018 15:23:04] "POST /InventoryApp/get_user/ HTTP/1.1" 200 112
[01/Feb/2018 15:23:04] "POST /InventoryApp/get_user/ HTTP/1.1" 200 112
[01/Feb/2018 15:23:04] "GET /InventoryApp/get_category/ HTTP/1.1" 200 190
[01/Feb/2018 15:23:06] "POST /InventoryApp/get_requisition/ HTTP/1.1" 200 812
[01/Feb/2018 15:23:06] "GET /InventoryApp/get_category/ HTTP/1.1" 200 190
[01/Feb/2018 15:23:12] "GET /InventoryApp/get_category/ HTTP/1.1" 200 190
[01/Feb/2018 15:23:12] "POST /InventoryApp/get_requisition/ HTTP/1.1" 200 812
[01/Feb/2018 15:30:50] "POST /InventoryApp/login/ HTTP/1.1" 200 53
[01/Feb/2018 15:30:51] "POST /InventoryApp/login/ HTTP/1.1" 200 53
[01/Feb/2018 15:30:51] "POST /InventoryApp/get_user/ HTTP/1.1" 200 112
[01/Feb/2018 15:30:52] "POST /InventoryApp/get_user/ HTTP/1.1" 200 112
[01/Feb/2018 15:30:52] "GET /InventoryApp/get_category/ HTTP/1.1" 200 190
[01/Feb/2018 15:30:52] "POST /InventoryApp/get_requisition/ HTTP/1.1" 200 812
[01/Feb/2018 15:30:53] "POST /InventoryApp/get_requisition/ HTTP/1.1" 200 812
[01/Feb/2018 15:30:53] "GET /InventoryApp/get_category/ HTTP/1.1" 200 190
[01/Feb/2018 15:31:06] "GET /InventoryApp/get_product/ HTTP/1.1" 200 399391
[01/Feb/2018 15:31:39] "POST /InventoryApp/login/ HTTP/1.1" 200 53
[01/Feb/2018 15:31:40] "POST /InventoryApp/get_user/ HTTP/1.1" 200 112
[01/Feb/2018 15:31:41] "POST /InventoryApp/get_requisition/ HTTP/1.1" 200 812
[01/Feb/2018 15:31:41] "GET /InventoryApp/get_category/ HTTP/1.1" 200 190
[01/Feb/2018 15:32:08] "POST /InventoryApp/login/ HTTP/1.1" 200 53
[01/Feb/2018 15:32:09] "POST /InventoryApp/get_user/ HTTP/1.1" 200 112
[01/Feb/2018 15:32:10] "POST /InventoryApp/get_requisition/ HTTP/1.1" 200 812
[01/Feb/2018 15:32:10] "GET /InventoryApp/get_category/ HTTP/1.1" 200 190
[01/Feb/2018 15:32:16] "GET /InventoryApp/get_product/ HTTP/1.1" 200 399391
[01/Feb/2018 15:32:41] "GET /InventoryApp/get_product/ HTTP/1.1" 200 399391
[01/Feb/2018 15:34:41] "POST /InventoryApp/login/ HTTP/1.1" 200 53
[01/Feb/2018 15:34:41] "POST /InventoryApp/get_user/ HTTP/1.1" 200 112
[01/Feb/2018 15:34:43] "POST /InventoryApp/get_requisition/ HTTP/1.1" 200 812
[01/Feb/2018 15:34:43] "GET /InventoryApp/get_category/ HTTP/1.1" 200 190
[01/Feb/2018 15:34:53] "POST /InventoryApp/get_requisitiondetails/ HTTP/1.1" 200 222
[01/Feb/2018 15:34:55] "GET /InventoryApp/get_product/ HTTP/1.1" 200 399391
[01/Feb/2018 15:35:35] "POST /InventoryApp/login/ HTTP/1.1" 200 53
[01/Feb/2018 15:35:36] "POST /InventoryApp/get_user/ HTTP/1.1" 200 112
[01/Feb/2018 15:35:37] "GET /InventoryApp/get_category/ HTTP/1.1" 200 190
[01/Feb/2018 15:35:37] "POST /InventoryApp/get_requisition/ HTTP/1.1" 200 812
[01/Feb/2018 15:35:42] "POST /InventoryApp/get_requisitiondetails/ HTTP/1.1" 200 222
[01/Feb/2018 15:35:44] "GET /InventoryApp/get_product/ HTTP/1.1" 200 399391
[01/Feb/2018 15:36:42] "POST /InventoryApp/login/ HTTP/1.1" 200 53
[01/Feb/2018 15:36:43] "POST /InventoryApp/get_user/ HTTP/1.1" 200 112
[01/Feb/2018 15:36:44] "POST /InventoryApp/get_requisition/ HTTP/1.1" 200 812
[01/Feb/2018 15:36:44] "GET /InventoryApp/get_category/ HTTP/1.1" 200 190
[01/Feb/2018 15:36:46] "POST /InventoryApp/get_requisitiondetails/ HTTP/1.1" 200 222
[01/Feb/2018 15:36:52] "GET /InventoryApp/get_product/ HTTP/1.1" 200 399391
[01/Feb/2018 15:47:13] "POST /InventoryApp/login/ HTTP/1.1" 200 53
[01/Feb/2018 15:47:13] "POST /InventoryApp/get_user/ HTTP/1.1" 200 112
[01/Feb/2018 15:47:14] "POST /InventoryApp/login/ HTTP/1.1" 200 53
[01/Feb/2018 15:47:15] "GET /InventoryApp/get_category/ HTTP/1.1" 200 190
[01/Feb/2018 15:47:15] "POST /InventoryApp/get_requisition/ HTTP/1.1" 200 812
[01/Feb/2018 15:47:15] "POST /InventoryApp/get_user/ HTTP/1.1" 200 112
[01/Feb/2018 15:47:16] "POST /InventoryApp/get_requisition/ HTTP/1.1" 200 812
[01/Feb/2018 15:47:16] "GET /InventoryApp/get_category/ HTTP/1.1" 200 190
[01/Feb/2018 15:47:21] "POST /InventoryApp/get_requisitiondetails/ HTTP/1.1" 200 222
[01/Feb/2018 15:47:23] "GET /InventoryApp/get_product/ HTTP/1.1" 200 399391
[01/Feb/2018 16:05:27] "POST /InventoryApp/login/ HTTP/1.1" 200 53
[01/Feb/2018 16:05:28] "POST /InventoryApp/get_user/ HTTP/1.1" 200 112
[01/Feb/2018 16:05:29] "POST /InventoryApp/login/ HTTP/1.1" 200 53
[01/Feb/2018 16:05:29] "POST /InventoryApp/get_user/ HTTP/1.1" 200 112
[01/Feb/2018 16:05:29] "POST /InventoryApp/get_requisition/ HTTP/1.1" 200 812
[01/Feb/2018 16:05:29] "GET /InventoryApp/get_category/ HTTP/1.1" 200 190
[01/Feb/2018 16:05:30] "POST /InventoryApp/get_requisition/ HTTP/1.1" 200 812
[01/Feb/2018 16:05:30] "GET /InventoryApp/get_category/ HTTP/1.1" 200 190
[01/Feb/2018 16:05:36] "POST /InventoryApp/get_requisitiondetails/ HTTP/1.1" 200 222
[01/Feb/2018 16:05:38] "GET /InventoryApp/get_product/ HTTP/1.1" 200 399391
[01/Feb/2018 16:08:40] "POST /InventoryApp/login/ HTTP/1.1" 200 53
[01/Feb/2018 16:08:41] "POST /InventoryApp/get_user/ HTTP/1.1" 200 112
[01/Feb/2018 16:08:42] "GET /InventoryApp/get_category/ HTTP/1.1" 200 190
[01/Feb/2018 16:08:42] "POST /InventoryApp/get_requisition/ HTTP/1.1" 200 812
[01/Feb/2018 16:08:46] "POST /InventoryApp/get_requisitiondetails/ HTTP/1.1" 200 199
[01/Feb/2018 16:08:48] "GET /InventoryApp/get_product/ HTTP/1.1" 200 399391
[01/Feb/2018 16:09:56] "GET /InventoryApp/get_category/ HTTP/1.1" 200 190
[01/Feb/2018 16:09:56] "POST /InventoryApp/get_requisition/ HTTP/1.1" 200 18
[01/Feb/2018 16:24:58] "POST /InventoryApp/login/ HTTP/1.1" 200 53
[01/Feb/2018 16:24:59] "POST /InventoryApp/login/ HTTP/1.1" 200 53
[01/Feb/2018 16:24:59] "POST /InventoryApp/get_user/ HTTP/1.1" 200 109
[01/Feb/2018 16:25:02] "POST /InventoryApp/get_user/ HTTP/1.1" 200 109
[01/Feb/2018 16:25:03] "POST /InventoryApp/login/ HTTP/1.1" 200 53
[01/Feb/2018 16:25:04] "POST /InventoryApp/get_user/ HTTP/1.1" 200 109
[01/Feb/2018 16:25:04] "POST /InventoryApp/get_requisition/ HTTP/1.1" 200 18
[01/Feb/2018 16:25:04] "GET /InventoryApp/get_category/ HTTP/1.1" 200 190
[01/Feb/2018 16:25:05] "GET /InventoryApp/get_category/ HTTP/1.1" 200 190
[01/Feb/2018 16:25:05] "POST /InventoryApp/get_requisition/ HTTP/1.1" 200 18
[01/Feb/2018 16:25:40] "POST /InventoryApp/login/ HTTP/1.1" 200 53
[01/Feb/2018 16:25:41] "POST /InventoryApp/get_user/ HTTP/1.1" 200 109
[01/Feb/2018 16:25:42] "POST /InventoryApp/get_requisition/ HTTP/1.1" 200 18
[01/Feb/2018 16:25:42] "GET /InventoryApp/get_category/ HTTP/1.1" 200 190
[01/Feb/2018 16:28:01] "POST /InventoryApp/login/ HTTP/1.1" 200 53
[01/Feb/2018 16:28:02] "POST /InventoryApp/get_user/ HTTP/1.1" 200 212
[01/Feb/2018 16:28:03] "POST /InventoryApp/login/ HTTP/1.1" 200 53
[01/Feb/2018 16:28:03] "POST /InventoryApp/get_requisition/ HTTP/1.1" 200 18
[01/Feb/2018 16:28:03] "GET /InventoryApp/get_category/ HTTP/1.1" 200 190
[01/Feb/2018 16:28:03] "POST /InventoryApp/get_user/ HTTP/1.1" 200 212
[01/Feb/2018 16:28:04] "GET /InventoryApp/get_category/ HTTP/1.1" 200 190
[01/Feb/2018 16:28:04] "POST /InventoryApp/get_requisition/ HTTP/1.1" 200 18
[01/Feb/2018 16:54:00] "GET /InventoryApp/get_empjobrole/ HTTP/1.1" 200 609
[01/Feb/2018 16:54:00] "GET /favicon.ico HTTP/1.1" 404 85
Performing system checks...

System check identified no issues (0 silenced).
February 01, 2018 - 15:06:58
Django version 1.11.7, using settings 'InventoryProject.settings'
Starting development server at http://0.0.0.0:20105/
Quit the server with CONTROL-C.
{"username":"johneda"}
{"password":"tabitha","username":"tabitha"}
{"username":"tabitha"}
{"id":"5"}
{"id":"20"}
{"password":"tabitha","username":"tabitha"}
{"username":"tabitha"}
{"id":"5"}
{"id":"5"}
{"password":"tabitha","username":"tabitha"}
{"username":"tabitha"}
{"password":"tabitha","username":"tabitha"}
{"id":"5"}
{"username":"tabitha"}
{"id":"5"}
{"password":"tabitha","username":"tabitha"}
{"username":"tabitha"}
{"id":"5"}
{"password":"tabitha","username":"tabitha"}
{"username":"tabitha"}
{"id":"5"}
{"password":"tabitha","username":"tabitha"}
{"password":"tabitha","username":"tabitha"}
{"password":"tabitha","username":"tabitha"}
{"password":"tabitha","username":"tabitha"}
{"password":"tabitha","username":"tabitha"}
{"username":"tabitha"}
{"id":"5"}
{"username":"tabitha"}
{"username":"tabitha"}
{"username":"tabitha"}
{"id":"5"}
{"id":"5"}
{"password":"tabitha","username":"tabitha"}
{"password":"tabitha","username":"tabitha"}
{"username":"tabitha"}
{"username":"tabitha"}
{"id":"5"}
{"id":"5"}
{"password":"tabitha","username":"tabitha"}
{"username":"tabitha"}
{"id":"5"}
{"password":"tabitha","username":"tabitha"}
{"username":"tabitha"}
{"id":"5"}
{"password":"tabitha","username":"tabitha"}
{"username":"tabitha"}
{"id":"5"}
{"id":"19"}
{"password":"tabitha","username":"tabitha"}
{"username":"tabitha"}
{"id":"5"}
{"id":"19"}
{"password":"tabitha","username":"tabitha"}
{"username":"tabitha"}
{"id":"5"}
{"id":"19"}
{"password":"tabitha","username":"tabitha"}
{"username":"tabitha"}
{"password":"tabitha","username":"tabitha"}
{"id":"5"}
{"username":"tabitha"}
{"id":"5"}
{"id":"19"}
{"password":"tabitha","username":"tabitha"}
{"username":"tabitha"}
{"password":"tabitha","username":"tabitha"}
{"username":"tabitha"}
{"id":"5"}
{"id":"5"}
{"id":"19"}
{"password":"tabitha","username":"tabitha"}
{"username":"tabitha"}
{"id":"5"}
{"id":"18"}
{"id":"null"}
{"password":"test","username":"test"}
{"password":"test","username":"test"}
{"username":"test"}
{"username":"test"}
{"password":"test","username":"test"}
{"username":"test"}
{"id":"8"}
{"id":"8"}
{"password":"test","username":"test"}
{"username":"test"}
{"id":"8"}
{"password":"chanti","username":"chanti"}
{"username":"chanti"}
{"password":"chanti","username":"chanti"}
{"id":"10"}
{"username":"chanti"}
{"id":"10"}
Performing system checks...

System check identified no issues (0 silenced).
February 01, 2018 - 16:55:26
Django version 1.11.7, using settings 'InventoryProject.settings'
Starting development server at http://0.0.0.0:20105/
Quit the server with CONTROL-C.
Unhandled exception in thread started by <function wrapper at 0x7f9ce3e478c0>
Traceback (most recent call last):
  File "/usr/local/lib/python2.7/dist-packages/django/utils/autoreload.py", line 228, in wrapper
    fn(*args, **kwargs)
  File "/usr/local/lib/python2.7/dist-packages/django/core/management/commands/runserver.py", line 117, in inner_run
    autoreload.raise_last_exception()
  File "/usr/local/lib/python2.7/dist-packages/django/utils/autoreload.py", line 251, in raise_last_exception
    six.reraise(*_exception)
  File "/usr/local/lib/python2.7/dist-packages/django/utils/autoreload.py", line 228, in wrapper
    fn(*args, **kwargs)
  File "/usr/local/lib/python2.7/dist-packages/django/__init__.py", line 27, in setup
    apps.populate(settings.INSTALLED_APPS)
  File "/usr/local/lib/python2.7/dist-packages/django/apps/registry.py", line 108, in populate
    app_config.import_models()
  File "/usr/local/lib/python2.7/dist-packages/django/apps/config.py", line 202, in import_models
    self.models_module = import_module(models_module_name)
  File "/usr/lib/python2.7/importlib/__init__.py", line 37, in import_module
    __import__(name)
  File "/home/esp/Desktop/InventoryProject/InventoryApp/models.py", line 168, in <module>
    class user_menus(models.Model):
  File "/home/esp/Desktop/InventoryProject/InventoryApp/models.py", line 171, in user_menus
    menuName = models.CharField(max_lenght = 30)
  File "/usr/local/lib/python2.7/dist-packages/django/db/models/fields/__init__.py", line 1061, in __init__
    super(CharField, self).__init__(*args, **kwargs)
TypeError: __init__() got an unexpected keyword argument 'max_lenght'
nohup: ignoring input
[01/Feb/2018 17:39:49] "POST /InventoryApp/get_user/ HTTP/1.1" 200 147
[01/Feb/2018 17:39:58] "POST /InventoryApp/get_user/ HTTP/1.1" 200 534
[01/Feb/2018 17:44:03] "POST /InventoryApp/get_user/ HTTP/1.1" 200 813
[01/Feb/2018 17:44:50] "POST /InventoryApp/login/ HTTP/1.1" 200 53
[01/Feb/2018 17:44:51] "POST /InventoryApp/login/ HTTP/1.1" 200 53
[01/Feb/2018 17:44:51] "POST /InventoryApp/get_user/ HTTP/1.1" 200 147
[01/Feb/2018 17:44:51] "POST /InventoryApp/login/ HTTP/1.1" 200 53
[01/Feb/2018 17:44:52] "POST /InventoryApp/login/ HTTP/1.1" 200 53
[01/Feb/2018 17:44:52] "POST /InventoryApp/get_user/ HTTP/1.1" 200 147
[01/Feb/2018 17:44:52] "POST /InventoryApp/get_user/ HTTP/1.1" 200 147
[01/Feb/2018 17:44:52] "GET /InventoryApp/get_category/ HTTP/1.1" 200 190
[01/Feb/2018 17:44:52] "POST /InventoryApp/get_requisition/ HTTP/1.1" 200 812
[01/Feb/2018 17:44:53] "POST /InventoryApp/get_user/ HTTP/1.1" 200 147
[01/Feb/2018 17:44:53] "GET /InventoryApp/get_category/ HTTP/1.1" 200 190
[01/Feb/2018 17:44:53] "POST /InventoryApp/get_requisition/ HTTP/1.1" 200 812
[01/Feb/2018 17:44:53] "GET /InventoryApp/get_category/ HTTP/1.1" 200 190
[01/Feb/2018 17:44:53] "POST /InventoryApp/get_requisition/ HTTP/1.1" 200 812
[01/Feb/2018 17:44:53] "POST /InventoryApp/get_requisition/ HTTP/1.1" 200 812
[01/Feb/2018 17:44:53] "GET /InventoryApp/get_category/ HTTP/1.1" 200 190
[01/Feb/2018 17:48:52] "POST /InventoryApp/get_user/ HTTP/1.1" 200 534
[01/Feb/2018 17:53:21] "POST /InventoryApp/get_requisitiondetails/ HTTP/1.1" 200 222
[01/Feb/2018 17:53:24] "GET /InventoryApp/get_product/ HTTP/1.1" 200 399391
[01/Feb/2018 18:01:59] "POST /InventoryApp/login/ HTTP/1.1" 200 53
[01/Feb/2018 18:01:59] "POST /InventoryApp/get_user/ HTTP/1.1" 200 147
[01/Feb/2018 18:02:00] "POST /InventoryApp/get_requisition/ HTTP/1.1" 200 812
[01/Feb/2018 18:02:00] "GET /InventoryApp/get_category/ HTTP/1.1" 200 190
[01/Feb/2018 18:09:54] "POST /InventoryApp/get_requisitiondetails/ HTTP/1.1" 200 199
[01/Feb/2018 18:09:56] "GET /InventoryApp/get_product/ HTTP/1.1" 200 399391
[01/Feb/2018 18:10:09] "POST /InventoryApp/get_requisitiondetails/ HTTP/1.1" 200 222
[01/Feb/2018 18:10:11] "GET /InventoryApp/get_product/ HTTP/1.1" 200 399391
Performing system checks...

System check identified no issues (0 silenced).
February 01, 2018 - 17:39:31
Django version 1.11.7, using settings 'InventoryProject.settings'
Starting development server at http://0.0.0.0:20105/
Quit the server with CONTROL-C.
{"username":"johneda"}
{"username":"phani"}
{"username":"chanti"}
{"password":"tabitha","username":"tabitha"}
{"password":"tabitha","username":"tabitha"}
{"password":"tabitha","username":"tabitha"}
{"username":"tabitha"}
 {"password":"tabitha","username":"tabitha"}
{"username":"tabitha"}
{"username":"tabitha"}
{"id":"5"}
{"username":"tabitha"}
{"id":"5"}
{"id":"5"}
{"id":"5"}
{"username":"phani"}
{"id":"19"}
{"password":"tabitha","username":"tabitha"}
{"username":"tabitha"}
{"id":"5"}
{"id":"18"}
{"id":"19"}
Unhandled exception in thread started by <function wrapper at 0x7f40ee1a2500>
Performing system checks...

Traceback (most recent call last):
  File "/usr/local/lib/python2.7/dist-packages/django/utils/autoreload.py", line 228, in wrapper
    fn(*args, **kwargs)
  File "/usr/local/lib/python2.7/dist-packages/django/core/management/commands/runserver.py", line 125, in inner_run
    self.check(display_num_errors=True)
  File "/usr/local/lib/python2.7/dist-packages/django/core/management/base.py", line 359, in check
    include_deployment_checks=include_deployment_checks,
  File "/usr/local/lib/python2.7/dist-packages/django/core/management/base.py", line 346, in _run_checks
    return checks.run_checks(**kwargs)
  File "/usr/local/lib/python2.7/dist-packages/django/core/checks/registry.py", line 81, in run_checks
    new_errors = check(app_configs=app_configs)
  File "/usr/local/lib/python2.7/dist-packages/django/core/checks/urls.py", line 16, in check_url_config
    return check_resolver(resolver)
  File "/usr/local/lib/python2.7/dist-packages/django/core/checks/urls.py", line 26, in check_resolver
    return check_method()
  File "/usr/local/lib/python2.7/dist-packages/django/urls/resolvers.py", line 254, in check
    for pattern in self.url_patterns:
  File "/usr/local/lib/python2.7/dist-packages/django/utils/functional.py", line 35, in __get__
    res = instance.__dict__[self.name] = self.func(instance)
  File "/usr/local/lib/python2.7/dist-packages/django/urls/resolvers.py", line 405, in url_patterns
    patterns = getattr(self.urlconf_module, "urlpatterns", self.urlconf_module)
  File "/usr/local/lib/python2.7/dist-packages/django/utils/functional.py", line 35, in __get__
    res = instance.__dict__[self.name] = self.func(instance)
  File "/usr/local/lib/python2.7/dist-packages/django/urls/resolvers.py", line 398, in urlconf_module
    return import_module(self.urlconf_name)
  File "/usr/lib/python2.7/importlib/__init__.py", line 37, in import_module
    __import__(name)
  File "/home/esp/Desktop/InventoryProject/InventoryProject/urls.py", line 18, in <module>
    from InventoryApp import urls
  File "/home/esp/Desktop/InventoryProject/InventoryApp/urls.py", line 6, in <module>
    url(r'^login/',csrf_exempt(login),name = 'login'),
NameError: name 'login' is not defined
Unhandled exception in thread started by <function wrapper at 0x7fbcdde5b500>
Performing system checks...

Traceback (most recent call last):
  File "/usr/local/lib/python2.7/dist-packages/django/utils/autoreload.py", line 228, in wrapper
    fn(*args, **kwargs)
  File "/usr/local/lib/python2.7/dist-packages/django/core/management/commands/runserver.py", line 125, in inner_run
    self.check(display_num_errors=True)
  File "/usr/local/lib/python2.7/dist-packages/django/core/management/base.py", line 359, in check
    include_deployment_checks=include_deployment_checks,
  File "/usr/local/lib/python2.7/dist-packages/django/core/management/base.py", line 346, in _run_checks
    return checks.run_checks(**kwargs)
  File "/usr/local/lib/python2.7/dist-packages/django/core/checks/registry.py", line 81, in run_checks
    new_errors = check(app_configs=app_configs)
  File "/usr/local/lib/python2.7/dist-packages/django/core/checks/urls.py", line 16, in check_url_config
    return check_resolver(resolver)
  File "/usr/local/lib/python2.7/dist-packages/django/core/checks/urls.py", line 26, in check_resolver
    return check_method()
  File "/usr/local/lib/python2.7/dist-packages/django/urls/resolvers.py", line 254, in check
    for pattern in self.url_patterns:
  File "/usr/local/lib/python2.7/dist-packages/django/utils/functional.py", line 35, in __get__
    res = instance.__dict__[self.name] = self.func(instance)
  File "/usr/local/lib/python2.7/dist-packages/django/urls/resolvers.py", line 405, in url_patterns
    patterns = getattr(self.urlconf_module, "urlpatterns", self.urlconf_module)
  File "/usr/local/lib/python2.7/dist-packages/django/utils/functional.py", line 35, in __get__
    res = instance.__dict__[self.name] = self.func(instance)
  File "/usr/local/lib/python2.7/dist-packages/django/urls/resolvers.py", line 398, in urlconf_module
    return import_module(self.urlconf_name)
  File "/usr/lib/python2.7/importlib/__init__.py", line 37, in import_module
    __import__(name)
  File "/home/esp/Desktop/InventoryProject/InventoryProject/urls.py", line 18, in <module>
    from InventoryApp import urls
  File "/home/esp/Desktop/InventoryProject/InventoryApp/urls.py", line 3, in <module>
    from InventoryApp.views import *
  File "/home/esp/Desktop/InventoryProject/InventoryApp/views.py", line 791
    
    ^
SyntaxError: EOF while scanning triple-quoted string literal
Unhandled exception in thread started by <function wrapper at 0x7f0b3eda4500>
Performing system checks...

Traceback (most recent call last):
  File "/usr/local/lib/python2.7/dist-packages/django/utils/autoreload.py", line 228, in wrapper
    fn(*args, **kwargs)
  File "/usr/local/lib/python2.7/dist-packages/django/core/management/commands/runserver.py", line 125, in inner_run
    self.check(display_num_errors=True)
  File "/usr/local/lib/python2.7/dist-packages/django/core/management/base.py", line 359, in check
    include_deployment_checks=include_deployment_checks,
  File "/usr/local/lib/python2.7/dist-packages/django/core/management/base.py", line 346, in _run_checks
    return checks.run_checks(**kwargs)
  File "/usr/local/lib/python2.7/dist-packages/django/core/checks/registry.py", line 81, in run_checks
    new_errors = check(app_configs=app_configs)
  File "/usr/local/lib/python2.7/dist-packages/django/core/checks/urls.py", line 16, in check_url_config
    return check_resolver(resolver)
  File "/usr/local/lib/python2.7/dist-packages/django/core/checks/urls.py", line 26, in check_resolver
    return check_method()
  File "/usr/local/lib/python2.7/dist-packages/django/urls/resolvers.py", line 254, in check
    for pattern in self.url_patterns:
  File "/usr/local/lib/python2.7/dist-packages/django/utils/functional.py", line 35, in __get__
    res = instance.__dict__[self.name] = self.func(instance)
  File "/usr/local/lib/python2.7/dist-packages/django/urls/resolvers.py", line 405, in url_patterns
    patterns = getattr(self.urlconf_module, "urlpatterns", self.urlconf_module)
  File "/usr/local/lib/python2.7/dist-packages/django/utils/functional.py", line 35, in __get__
    res = instance.__dict__[self.name] = self.func(instance)
  File "/usr/local/lib/python2.7/dist-packages/django/urls/resolvers.py", line 398, in urlconf_module
    return import_module(self.urlconf_name)
  File "/usr/lib/python2.7/importlib/__init__.py", line 37, in import_module
    __import__(name)
  File "/home/esp/Desktop/InventoryProject/InventoryProject/urls.py", line 18, in <module>
    from InventoryApp import urls
  File "/home/esp/Desktop/InventoryProject/InventoryApp/urls.py", line 3, in <module>
    from InventoryApp.views import *
  File "/home/esp/Desktop/InventoryProject/InventoryApp/views.py", line 1596
    if((data1.get('locationname') is None) or ((data1.get('locationna
                                                                    ^
SyntaxError: EOL while scanning string literal
[01/Feb/2018 18:28:10] "POST /InventoryApp/get_user/ HTTP/1.1" 200 306
[01/Feb/2018 18:28:19] "POST /InventoryApp/get_user/ HTTP/1.1" 200 117
[01/Feb/2018 18:28:27] "POST /InventoryApp/get_user/ HTTP/1.1" 200 504
[01/Feb/2018 18:29:33] "POST /InventoryApp/get_user/ HTTP/1.1" 200 117
[01/Feb/2018 18:29:42] "POST /InventoryApp/login/ HTTP/1.1" 200 53
[01/Feb/2018 18:29:43] "POST /InventoryApp/get_user/ HTTP/1.1" 200 117
[01/Feb/2018 18:29:44] "POST /InventoryApp/get_requisition/ HTTP/1.1" 200 812
[01/Feb/2018 18:29:44] "GET /InventoryApp/get_category/ HTTP/1.1" 200 190
[01/Feb/2018 18:30:14] "POST /InventoryApp/login/ HTTP/1.1" 200 53
[01/Feb/2018 18:30:15] "POST /InventoryApp/get_user/ HTTP/1.1" 200 504
[01/Feb/2018 18:30:15] "POST /InventoryApp/get_user/ HTTP/1.1" 200 114
[01/Feb/2018 18:30:16] "GET /InventoryApp/get_category/ HTTP/1.1" 200 190
[01/Feb/2018 18:30:16] "POST /InventoryApp/get_requisition/ HTTP/1.1" 200 18
[01/Feb/2018 18:31:56] "POST /InventoryApp/get_user/ HTTP/1.1" 200 597
[01/Feb/2018 18:32:00] "POST /InventoryApp/login/ HTTP/1.1" 200 53
[01/Feb/2018 18:32:07] "POST /InventoryApp/login/ HTTP/1.1" 200 53
[01/Feb/2018 18:32:32] "POST /InventoryApp/login/ HTTP/1.1" 200 53
[01/Feb/2018 18:32:36] "POST /InventoryApp/login/ HTTP/1.1" 200 53
[01/Feb/2018 18:32:42] "POST /InventoryApp/get_user/ HTTP/1.1" 200 597
[01/Feb/2018 18:32:44] "POST /InventoryApp/get_requisition/ HTTP/1.1" 200 18
[01/Feb/2018 18:32:44] "GET /InventoryApp/get_category/ HTTP/1.1" 200 190
